Workbook

Sheet README
A1: RISA-3D Material Library in Imperial and Standard Metric, for Python Solver Rev.2
A3: Source: nine screenshots in the Materials folder (RISA-3D Materials spreadsheet, one sheet per tab, plus the Masonry Self Weight dialog).
A4: Two unit sets on every sheet: the Imperial table (ksi, k/ft³, 1e-5/°F) as transcribed from RISA, and below it a Standard Metric table (MPa, kN/m³, kg/m³, 1e-6/°C) computed by formula from the Imperial rows.
A5: All conversion factors live on the Conversion Factors sheet and are formulas built from three exact definitions: 1 in = 25.4 mm, 1 lbf = 4.4482216152605 N, g = 9.80665 m/s².
A6: Blue numbers are transcribed inputs. Black cells in the green-shaded 'Solver check' columns are live formulas and recalculate if an input is edited.
A7: The 'All Materials' sheet is a flat, solver-ready table: one row per material with SI conversions computed by formula.
A8: Notes on the source screenshots:
A9: Wood rows 7 to 12: labels are truncated on screen; the full label was reconstructed from the Species column.
A10: Aluminum row 6: label reads '6061-T6...' on screen; strengths (Ftu 24, Fty 15 ksi) match welded 6061-T6, so it is labelled '6061-T6 (welded)'.
A11: Stainless SS1: the numbers sit under ksi headers but have SI magnitudes (193,100 MPa, 206.843 MPa = 30 ksi, 517.107 MPa = 75 ksi). Recorded as displayed; check the RISA unit setting before using this row.
A12: General RIGID: G is blank in RISA; E is 1e+6 ksi.
A14: Sheet index
A15: Conversion Factors | B15: Exact definitions and every derived Imperial/Metric factor, as formulas
A16: Hot Rolled | B16: Hot rolled steel: A36, A572, A992, A500
A17: Cold Formed | B17: Cold formed steel: A570, A607
A18: Wood | B18: Solid sawn, glulam and LVL species keys
A19: Concrete | B19: Normal and lightweight, 3 to 4 ksi
A20: Masonry | B20: Concrete and clay masonry plus self-weight settings
A21: Aluminum | B21: 3003, 5052, 6061, 6063 alloys
A22: Stainless | B22: SS1 with Ramberg-Osgood n
A23: General | B23: Generic isotropic materials and RIGID
A24: All Materials | B24: Flat solver-ready table, Imperial and Metric side by side
A25: Glossary | B25: What every column means and how the solver uses it

Sheet Conversion Factors
A1: Conversion factors, Imperial to Standard Metric, derived from exact definitions
A3: Base definitions (exact, NIST SP 811). Blue = input; everything below is a formula.
A4: 1 inch in millimetres | B4: 25.4 | C4: mm
A5: 1 pound-force in newtons | B5: 4.4482216 | C5: N
A6: Standard gravity | B6: 9.80665 | C6: m/s²
A7: Kip = 1000 lbf | B7: 1000 | C7: lbf
A8: Foot = 12 inches | B8: 12 | C8: in
A10: Derived factors
A11: Quantity | B11: Imperial unit | C11: Metric unit | D11: Multiply Imperial by | E11: Metric to Imperial | F11: Derivation
A12: Length | B12: in | C12: mm | D12: =$B$4 -> 25.4 | E12: =1/D12 -> 0.039370079 | F12: 1 in = 25.4 mm
A13: Length | B13: ft | C13: m | D13: =$B$4*$B$8/1000 -> 0.3048 | E13: =1/D13 -> 3.2808399 | F13: 12 × 25.4 / 1000
A14: Area | B14: in² | C14: mm² | D14: =$B$4^2 -> 645.16 | E14: =1/D14 -> 0.0015500031 | F14: 25.4²
A15: Moment of inertia | B15: in⁴ | C15: mm⁴ | D15: =$B$4^4 -> 416231.43 | E15: =1/D15 -> 2.4025096e-06 | F15: 25.4⁴
A16: Force | B16: kip | C16: kN | D16: =$B$5*$B$7/1000 -> 4.4482216 | E16: =1/D16 -> 0.22480894 | F16: 4.448222 N × 1000 / 1000
A17: Moment | B17: kip·ft | C17: kN·m | D17: =$B$5*$B$7/1000*$B$4*$B$8/1000 -> 1.3558179 | E17: =1/D17 -> 0.73756215 | F17: kN × m
A18: Stress / modulus | B18: ksi | C18: MPa | D18: =$B$5*$B$7/($B$4^2) -> 6.8947573 | E18: =1/D18 -> 0.14503774 | F18: kN / mm² × 1000 = N/mm²
A19: Stress / modulus | B19: ksi | C19: GPa | D19: =$B$5*$B$7/($B$4^2)/1000 -> 0.0068947573 | E19: =1/D19 -> 145.03774 | F19: MPa / 1000
A20: Distributed load | B20: kip/ft | C20: kN/m | D20: =$B$5*$B$7/1000/($B$4*$B$8/1000) -> 14.593903 | E20: =1/D20 -> 0.068521766 | F20: kN / m
A21: Unit weight | B21: k/ft³ | C21: kN/m³ | D21: =$B$5*$B$7/1000/(($B$4*$B$8/1000)^3) -> 157.08746 | E21: =1/D21 -> 0.0063658804 | F21: kN / m³
A22: Mass density from unit weight | B22: k/ft³ | C22: kg/m³ | D22: =$B$5*$B$7/(($B$4*$B$8/1000)^3)/$B$6 -> 16018.463 | E22: =1/D22 -> 6.2427961e-05 | F22: N/m³ ÷ g
A23: Thermal coefficient | B23: 1e-5 /°F | C23: 1e-6 /°C | D23: =1.8*10 -> 18 | E23: =1/D23 -> 0.055555556 | F23: per °F × 1.8 = per °C; 1e-5 → 1e-6 is × 10

Sheet Hot Rolled
A1: Hot Rolled Materials (RISA-3D)
A2: Source screenshot: Materials-SS-Hot-Rolled-TAB.png. Blue = transcribed input. Green = live formula check.
A3: Imperial (as shown in RISA): ksi, k/ft³, 1e-5/°F
A4: Label | B4: E [ksi] | C4: G [ksi] | D4: Nu | E4: Therm. Coeff. [1e-5/°F] | F4: Density [k/ft³] | G4: Yield [ksi] | H4: Ry | I4: Fu [ksi] | J4: Rt | L4: Solver check: G = E/(2(1+Nu)) [ksi] | M4: Diff vs table G
A5: A36 Gr.36 | B5: 29000 | C5: 11154 | D5: 0.3 | E5: 0.65 | F5: 0.49 | G5: 36 | H5: 1.5 | I5: 58 | J5: 1.2 | L5: =B5/(2*(1+D5)) -> 11153.846 | M5: =IF(ISNUMBER(C5),(C5-L5)/L5,"n/a") -> 1.3793103e-05
A6: A572 Gr.50 | B6: 29000 | C6: 11154 | D6: 0.3 | E6: 0.65 | F6: 0.49 | G6: 50 | H6: 1.1 | I6: 58 | J6: 1.2 | L6: =B6/(2*(1+D6)) -> 11153.846 | M6: =IF(ISNUMBER(C6),(C6-L6)/L6,"n/a") -> 1.3793103e-05
A7: A992 | B7: 29000 | C7: 11154 | D7: 0.3 | E7: 0.65 | F7: 0.49 | G7: 50 | H7: 1.1 | I7: 58 | J7: 1.2 | L7: =B7/(2*(1+D7)) -> 11153.846 | M7: =IF(ISNUMBER(C7),(C7-L7)/L7,"n/a") -> 1.3793103e-05
A8: A500 Gr.42 | B8: 29000 | C8: 11154 | D8: 0.3 | E8: 0.65 | F8: 0.49 | G8: 42 | H8: 1.3 | I8: 58 | J8: 1.1 | L8: =B8/(2*(1+D8)) -> 11153.846 | M8: =IF(ISNUMBER(C8),(C8-L8)/L8,"n/a") -> 1.3793103e-05
A9: A500 Gr.46 | B9: 29000 | C9: 11154 | D9: 0.3 | E9: 0.65 | F9: 0.49 | G9: 46 | H9: 1.2 | I9: 58 | J9: 1.1 | L9: =B9/(2*(1+D9)) -> 11153.846 | M9: =IF(ISNUMBER(C9),(C9-L9)/L9,"n/a") -> 1.3793103e-05
A11: Standard Metric (SI), computed by formula from the Imperial table above
A12: Label | B12: E [MPa] | C12: G [MPa] | D12: Nu | E12: Therm. Coeff. [1e-6/°C] | F12: Density [kN/m³] | G12: Yield [MPa] | H12: Ry | I12: Fu [MPa] | J12: Rt | K12: Mass Density [kg/m³] | L12: E [GPa]
A13: =IF(A5="","",A5) -> A36 Gr.36 | B13: =IF(B5="","",IF(ISNUMBER(B5),B5*'Conversion Factors'!$D$18,B5)) -> 199947.96 | C13: =IF(C5="","",IF(ISNUMBER(C5),C5*'Conversion Factors'!$D$18,C5)) -> 76904.123 | D13: =IF(D5="","",D5) -> 0.3 | E13: =IF(E5="","",IF(ISNUMBER(E5),E5*'Conversion Factors'!$D$23,E5)) -> 11.7 | F13: =IF(F5="","",IF(ISNUMBER(F5),F5*'Conversion Factors'!$D$21,F5)) -> 76.972857 | G13: =IF(G5="","",IF(ISNUMBER(G5),G5*'Conversion Factors'!$D$18,G5)) -> 248.21126 | H13: =IF(H5="","",H5) -> 1.5 | I13: =IF(I5="","",IF(ISNUMBER(I5),I5*'Conversion Factors'!$D$18,I5)) -> 399.89592 | J13: =IF(J5="","",J5) -> 1.2 | K13: =IF(F5="","",IF(ISNUMBER(F5),F5*'Conversion Factors'!$D$22,F5)) -> 7849.0471 | L13: =IF(B5="","",IF(ISNUMBER(B5),B5*'Conversion Factors'!$D$18/1000,B5)) -> 199.94796
A14: =IF(A6="","",A6) -> A572 Gr.50 | B14: =IF(B6="","",IF(ISNUMBER(B6),B6*'Conversion Factors'!$D$18,B6)) -> 199947.96 | C14: =IF(C6="","",IF(ISNUMBER(C6),C6*'Conversion Factors'!$D$18,C6)) -> 76904.123 | D14: =IF(D6="","",D6) -> 0.3 | E14: =IF(E6="","",IF(ISNUMBER(E6),E6*'Conversion Factors'!$D$23,E6)) -> 11.7 | F14: =IF(F6="","",IF(ISNUMBER(F6),F6*'Conversion Factors'!$D$21,F6)) -> 76.972857 | G14: =IF(G6="","",IF(ISNUMBER(G6),G6*'Conversion Factors'!$D$18,G6)) -> 344.73786 | H14: =IF(H6="","",H6) -> 1.1 | I14: =IF(I6="","",IF(ISNUMBER(I6),I6*'Conversion Factors'!$D$18,I6)) -> 399.89592 | J14: =IF(J6="","",J6) -> 1.2 | K14: =IF(F6="","",IF(ISNUMBER(F6),F6*'Conversion Factors'!$D$22,F6)) -> 7849.0471 | L14: =IF(B6="","",IF(ISNUMBER(B6),B6*'Conversion Factors'!$D$18/1000,B6)) -> 199.94796
A15: =IF(A7="","",A7) -> A992 | B15: =IF(B7="","",IF(ISNUMBER(B7),B7*'Conversion Factors'!$D$18,B7)) -> 199947.96 | C15: =IF(C7="","",IF(ISNUMBER(C7),C7*'Conversion Factors'!$D$18,C7)) -> 76904.123 | D15: =IF(D7="","",D7) -> 0.3 | E15: =IF(E7="","",IF(ISNUMBER(E7),E7*'Conversion Factors'!$D$23,E7)) -> 11.7 | F15: =IF(F7="","",IF(ISNUMBER(F7),F7*'Conversion Factors'!$D$21,F7)) -> 76.972857 | G15: =IF(G7="","",IF(ISNUMBER(G7),G7*'Conversion Factors'!$D$18,G7)) -> 344.73786 | H15: =IF(H7="","",H7) -> 1.1 | I15: =IF(I7="","",IF(ISNUMBER(I7),I7*'Conversion Factors'!$D$18,I7)) -> 399.89592 | J15: =IF(J7="","",J7) -> 1.2 | K15: =IF(F7="","",IF(ISNUMBER(F7),F7*'Conversion Factors'!$D$22,F7)) -> 7849.0471 | L15: =IF(B7="","",IF(ISNUMBER(B7),B7*'Conversion Factors'!$D$18/1000,B7)) -> 199.94796
A16: =IF(A8="","",A8) -> A500 Gr.42 | B16: =IF(B8="","",IF(ISNUMBER(B8),B8*'Conversion Factors'!$D$18,B8)) -> 199947.96 | C16: =IF(C8="","",IF(ISNUMBER(C8),C8*'Conversion Factors'!$D$18,C8)) -> 76904.123 | D16: =IF(D8="","",D8) -> 0.3 | E16: =IF(E8="","",IF(ISNUMBER(E8),E8*'Conversion Factors'!$D$23,E8)) -> 11.7 | F16: =IF(F8="","",IF(ISNUMBER(F8),F8*'Conversion Factors'!$D$21,F8)) -> 76.972857 | G16: =IF(G8="","",IF(ISNUMBER(G8),G8*'Conversion Factors'!$D$18,G8)) -> 289.57981 | H16: =IF(H8="","",H8) -> 1.3 | I16: =IF(I8="","",IF(ISNUMBER(I8),I8*'Conversion Factors'!$D$18,I8)) -> 399.89592 | J16: =IF(J8="","",J8) -> 1.1 | K16: =IF(F8="","",IF(ISNUMBER(F8),F8*'Conversion Factors'!$D$22,F8)) -> 7849.0471 | L16: =IF(B8="","",IF(ISNUMBER(B8),B8*'Conversion Factors'!$D$18/1000,B8)) -> 199.94796
A17: =IF(A9="","",A9) -> A500 Gr.46 | B17: =IF(B9="","",IF(ISNUMBER(B9),B9*'Conversion Factors'!$D$18,B9)) -> 199947.96 | C17: =IF(C9="","",IF(ISNUMBER(C9),C9*'Conversion Factors'!$D$18,C9)) -> 76904.123 | D17: =IF(D9="","",D9) -> 0.3 | E17: =IF(E9="","",IF(ISNUMBER(E9),E9*'Conversion Factors'!$D$23,E9)) -> 11.7 | F17: =IF(F9="","",IF(ISNUMBER(F9),F9*'Conversion Factors'!$D$21,F9)) -> 76.972857 | G17: =IF(G9="","",IF(ISNUMBER(G9),G9*'Conversion Factors'!$D$18,G9)) -> 317.15884 | H17: =IF(H9="","",H9) -> 1.2 | I17: =IF(I9="","",IF(ISNUMBER(I9),I9*'Conversion Factors'!$D$18,I9)) -> 399.89592 | J17: =IF(J9="","",J9) -> 1.1 | K17: =IF(F9="","",IF(ISNUMBER(F9),F9*'Conversion Factors'!$D$22,F9)) -> 7849.0471 | L17: =IF(B9="","",IF(ISNUMBER(B9),B9*'Conversion Factors'!$D$18/1000,B9)) -> 199.94796

Sheet Cold Formed
A1: Cold Formed Materials (RISA-3D)
A2: Source screenshot: Materials-SS-Cold-Formed-TAB.png. Blue = transcribed input. Green = live formula check.
A3: Imperial (as shown in RISA): ksi, k/ft³, 1e-5/°F
A4: Label | B4: E [ksi] | C4: G [ksi] | D4: Nu | E4: Therm. Coeff. [1e-5/°F] | F4: Density [k/ft³] | G4: Yield [ksi] | H4: Fu [ksi] | J4: Solver check: G = E/(2(1+Nu)) [ksi] | K4: Diff vs table G
A5: A570_33 | B5: 29500 | C5: 11346 | D5: 0.3 | E5: 0.65 | F5: 0.49 | G5: 33 | H5: 52 | J5: =B5/(2*(1+D5)) -> 11346.154 | K5: =IF(ISNUMBER(C5),(C5-J5)/J5,"n/a") -> -1.3559322e-05
A6: A607_C1_55 | B6: 29500 | C6: 11346 | D6: 0.3 | E6: 0.65 | F6: 0.49 | G6: 55 | H6: 70 | J6: =B6/(2*(1+D6)) -> 11346.154 | K6: =IF(ISNUMBER(C6),(C6-J6)/J6,"n/a") -> -1.3559322e-05
A8: Standard Metric (SI), computed by formula from the Imperial table above
A9: Label | B9: E [MPa] | C9: G [MPa] | D9: Nu | E9: Therm. Coeff. [1e-6/°C] | F9: Density [kN/m³] | G9: Yield [MPa] | H9: Fu [MPa] | I9: Mass Density [kg/m³] | J9: E [GPa]
A10: =IF(A5="","",A5) -> A570_33 | B10: =IF(B5="","",IF(ISNUMBER(B5),B5*'Conversion Factors'!$D$18,B5)) -> 203395.34 | C10: =IF(C5="","",IF(ISNUMBER(C5),C5*'Conversion Factors'!$D$18,C5)) -> 78227.916 | D10: =IF(D5="","",D5) -> 0.3 | E10: =IF(E5="","",IF(ISNUMBER(E5),E5*'Conversion Factors'!$D$23,E5)) -> 11.7 | F10: =IF(F5="","",IF(ISNUMBER(F5),F5*'Conversion Factors'!$D$21,F5)) -> 76.972857 | G10: =IF(G5="","",IF(ISNUMBER(G5),G5*'Conversion Factors'!$D$18,G5)) -> 227.52699 | H10: =IF(H5="","",IF(ISNUMBER(H5),H5*'Conversion Factors'!$D$18,H5)) -> 358.52738 | I10: =IF(F5="","",IF(ISNUMBER(F5),F5*'Conversion Factors'!$D$22,F5)) -> 7849.0471 | J10: =IF(B5="","",IF(ISNUMBER(B5),B5*'Conversion Factors'!$D$18/1000,B5)) -> 203.39534
A11: =IF(A6="","",A6) -> A607_C1_55 | B11: =IF(B6="","",IF(ISNUMBER(B6),B6*'Conversion Factors'!$D$18,B6)) -> 203395.34 | C11: =IF(C6="","",IF(ISNUMBER(C6),C6*'Conversion Factors'!$D$18,C6)) -> 78227.916 | D11: =IF(D6="","",D6) -> 0.3 | E11: =IF(E6="","",IF(ISNUMBER(E6),E6*'Conversion Factors'!$D$23,E6)) -> 11.7 | F11: =IF(F6="","",IF(ISNUMBER(F6),F6*'Conversion Factors'!$D$21,F6)) -> 76.972857 | G11: =IF(G6="","",IF(ISNUMBER(G6),G6*'Conversion Factors'!$D$18,G6)) -> 379.21165 | H11: =IF(H6="","",IF(ISNUMBER(H6),H6*'Conversion Factors'!$D$18,H6)) -> 482.63301 | I11: =IF(F6="","",IF(ISNUMBER(F6),F6*'Conversion Factors'!$D$22,F6)) -> 7849.0471 | J11: =IF(B6="","",IF(ISNUMBER(B6),B6*'Conversion Factors'!$D$18/1000,B6)) -> 203.39534

Sheet Wood
A1: Wood Materials (RISA-3D)
A2: Source screenshot: Materials-SS-Wood-TAB.png. Blue = transcribed input. Green = live formula check.
A3: Imperial (as shown in RISA): ksi, k/ft³, 1e-5/°F
A4: Label | B4: Type | C4: Database | D4: Species | E4: Grade | F4: Cm | G4: Ci | H4: Emod | I4: Nu | J4: Therm. Coeff. [1e-5/°F] | K4: Density [k/ft³]
A5: DF/SPine | B5: Solid Sawn | C5: Visually Graded | D5: Com Species Group I DF,SP | E5: No.1 | F5: No | G5: No | H5: 1 | I5: 0.3 | J5: 0.3 | K5: 0.035
A6: HF/Spruce Fir | B6: Solid Sawn | C6: Visually Graded | D6: Com Species Group II HF,SPF | E6: No.1 | F6: No | G6: No | H6: 1 | I6: 0.3 | J6: 0.3 | K6: 0.035
A7: DF | B7: Solid Sawn | C7: Visually Graded | D7: Douglas Fir-Larch | E7: No.1 | F7: No | G7: No | H7: 1 | I7: 0.3 | J7: 0.3 | K7: 0.035
A8: SP | B8: Solid Sawn | C8: Visually Graded | D8: Southern Pine | E8: No.1 | F8: No | G8: No | H8: 1 | I8: 0.3 | J8: 0.3 | K8: 0.035
A9: HF | B9: Solid Sawn | C9: Visually Graded | D9: Hem-Fir | E9: No.1 | F9: No | G9: No | H9: 1 | I9: 0.3 | J9: 0.3 | K9: 0.035
A10: SPF | B10: Solid Sawn | C10: Visually Graded | D10: Spruce-Pine-fir | E10: No.1 | F10: No | G10: No | H10: 1 | I10: 0.3 | J10: 0.3 | K10: 0.035
A11: 24F-1.8E DF_BAL | B11: Glulam | C11: NDS Table 5A | D11: 24F-1.8E_DF_BAL | E11: na | F11: No | G11: No | H11: 1 | I11: 0.3 | J11: 0.3 | K11: 0.035
A12: 24F-1.8E DF_UNBAL | B12: Glulam | C12: NDS Table 5A | D12: 24F-1.8E_DF_UNBAL | E12: na | F12: No | G12: No | H12: 1 | I12: 0.3 | J12: 0.3 | K12: 0.035
A13: 24F-1.8E SP_BAL | B13: Glulam | C13: NDS Table 5A | D13: 24F-1.8E_SP_BAL | E13: na | F13: No | G13: No | H13: 1 | I13: 0.3 | J13: 0.3 | K13: 0.035
A14: 24F-1.8E SP_UNBAL | B14: Glulam | C14: NDS Table 5A | D14: 24F-1.8E_SP_UNBAL | E14: na | F14: No | G14: No | H14: 1 | I14: 0.3 | J14: 0.3 | K14: 0.035
A15: LVL-PRL 1.5E_2250F | B15: Custom | C15: N/A | D15: LVL_PRL_1.5E_2250F | E15: na | F15: No | G15: No | H15: 1 | I15: 0.3 | J15: 0.3 | K15: 0.035
A16: LVL-PRL 2.0E_2900F | B16: Custom | C16: N/A | D16: LVL_PRL_2.0E_2900F | E16: na | F16: No | G16: No | H16: 1 | I16: 0.3 | J16: 0.3 | K16: 0.035
A18: Standard Metric (SI), computed by formula from the Imperial table above
A19: Label | B19: Type | C19: Database | D19: Species | E19: Grade | F19: Cm | G19: Ci | H19: Emod | I19: Nu | J19: Therm. Coeff. [1e-6/°C] | K19: Density [kN/m³] | L19: Mass Density [kg/m³]
A20: =IF(A5="","",A5) -> DF/SPine | B20: =IF(B5="","",B5) -> Solid Sawn | C20: =IF(C5="","",C5) -> Visually Graded | D20: =IF(D5="","",D5) -> Com Species Group I DF,SP | E20: =IF(E5="","",E5) -> No.1 | F20: =IF(F5="","",F5) -> No | G20: =IF(G5="","",G5) -> No | H20: =IF(H5="","",H5) -> 1 | I20: =IF(I5="","",I5) -> 0.3 | J20: =IF(J5="","",IF(ISNUMBER(J5),J5*'Conversion Factors'!$D$23,J5)) -> 5.4 | K20: =IF(K5="","",IF(ISNUMBER(K5),K5*'Conversion Factors'!$D$21,K5)) -> 5.4980612 | L20: =IF(K5="","",IF(ISNUMBER(K5),K5*'Conversion Factors'!$D$22,K5)) -> 560.64622
A21: =IF(A6="","",A6) -> HF/Spruce Fir | B21: =IF(B6="","",B6) -> Solid Sawn | C21: =IF(C6="","",C6) -> Visually Graded | D21: =IF(D6="","",D6) -> Com Species Group II HF,SPF | E21: =IF(E6="","",E6) -> No.1 | F21: =IF(F6="","",F6) -> No | G21: =IF(G6="","",G6) -> No | H21: =IF(H6="","",H6) -> 1 | I21: =IF(I6="","",I6) -> 0.3 | J21: =IF(J6="","",IF(ISNUMBER(J6),J6*'Conversion Factors'!$D$23,J6)) -> 5.4 | K21: =IF(K6="","",IF(ISNUMBER(K6),K6*'Conversion Factors'!$D$21,K6)) -> 5.4980612 | L21: =IF(K6="","",IF(ISNUMBER(K6),K6*'Conversion Factors'!$D$22,K6)) -> 560.64622
A22: =IF(A7="","",A7) -> DF | B22: =IF(B7="","",B7) -> Solid Sawn | C22: =IF(C7="","",C7) -> Visually Graded | D22: =IF(D7="","",D7) -> Douglas Fir-Larch | E22: =IF(E7="","",E7) -> No.1 | F22: =IF(F7="","",F7) -> No | G22: =IF(G7="","",G7) -> No | H22: =IF(H7="","",H7) -> 1 | I22: =IF(I7="","",I7) -> 0.3 | J22: =IF(J7="","",IF(ISNUMBER(J7),J7*'Conversion Factors'!$D$23,J7)) -> 5.4 | K22: =IF(K7="","",IF(ISNUMBER(K7),K7*'Conversion Factors'!$D$21,K7)) -> 5.4980612 | L22: =IF(K7="","",IF(ISNUMBER(K7),K7*'Conversion Factors'!$D$22,K7)) -> 560.64622
A23: =IF(A8="","",A8) -> SP | B23: =IF(B8="","",B8) -> Solid Sawn | C23: =IF(C8="","",C8) -> Visually Graded | D23: =IF(D8="","",D8) -> Southern Pine | E23: =IF(E8="","",E8) -> No.1 | F23: =IF(F8="","",F8) -> No | G23: =IF(G8="","",G8) -> No | H23: =IF(H8="","",H8) -> 1 | I23: =IF(I8="","",I8) -> 0.3 | J23: =IF(J8="","",IF(ISNUMBER(J8),J8*'Conversion Factors'!$D$23,J8)) -> 5.4 | K23: =IF(K8="","",IF(ISNUMBER(K8),K8*'Conversion Factors'!$D$21,K8)) -> 5.4980612 | L23: =IF(K8="","",IF(ISNUMBER(K8),K8*'Conversion Factors'!$D$22,K8)) -> 560.64622
A24: =IF(A9="","",A9) -> HF | B24: =IF(B9="","",B9) -> Solid Sawn | C24: =IF(C9="","",C9) -> Visually Graded | D24: =IF(D9="","",D9) -> Hem-Fir | E24: =IF(E9="","",E9) -> No.1 | F24: =IF(F9="","",F9) -> No | G24: =IF(G9="","",G9) -> No | H24: =IF(H9="","",H9) -> 1 | I24: =IF(I9="","",I9) -> 0.3 | J24: =IF(J9="","",IF(ISNUMBER(J9),J9*'Conversion Factors'!$D$23,J9)) -> 5.4 | K24: =IF(K9="","",IF(ISNUMBER(K9),K9*'Conversion Factors'!$D$21,K9)) -> 5.4980612 | L24: =IF(K9="","",IF(ISNUMBER(K9),K9*'Conversion Factors'!$D$22,K9)) -> 560.64622
A25: =IF(A10="","",A10) -> SPF | B25: =IF(B10="","",B10) -> Solid Sawn | C25: =IF(C10="","",C10) -> Visually Graded | D25: =IF(D10="","",D10) -> Spruce-Pine-fir | E25: =IF(E10="","",E10) -> No.1 | F25: =IF(F10="","",F10) -> No | G25: =IF(G10="","",G10) -> No | H25: =IF(H10="","",H10) -> 1 | I25: =IF(I10="","",I10) -> 0.3 | J25: =IF(J10="","",IF(ISNUMBER(J10),J10*'Conversion Factors'!$D$23,J10)) -> 5.4 | K25: =IF(K10="","",IF(ISNUMBER(K10),K10*'Conversion Factors'!$D$21,K10)) -> 5.4980612 | L25: =IF(K10="","",IF(ISNUMBER(K10),K10*'Conversion Factors'!$D$22,K10)) -> 560.64622
A26: =IF(A11="","",A11) -> 24F-1.8E DF_BAL | B26: =IF(B11="","",B11) -> Glulam | C26: =IF(C11="","",C11) -> NDS Table 5A | D26: =IF(D11="","",D11) -> 24F-1.8E_DF_BAL | E26: =IF(E11="","",E11) -> na | F26: =IF(F11="","",F11) -> No | G26: =IF(G11="","",G11) -> No | H26: =IF(H11="","",H11) -> 1 | I26: =IF(I11="","",I11) -> 0.3 | J26: =IF(J11="","",IF(ISNUMBER(J11),J11*'Conversion Factors'!$D$23,J11)) -> 5.4 | K26: =IF(K11="","",IF(ISNUMBER(K11),K11*'Conversion Factors'!$D$21,K11)) -> 5.4980612 | L26: =IF(K11="","",IF(ISNUMBER(K11),K11*'Conversion Factors'!$D$22,K11)) -> 560.64622
A27: =IF(A12="","",A12) -> 24F-1.8E DF_UNBAL | B27: =IF(B12="","",B12) -> Glulam | C27: =IF(C12="","",C12) -> NDS Table 5A | D27: =IF(D12="","",D12) -> 24F-1.8E_DF_UNBAL | E27: =IF(E12="","",E12) -> na | F27: =IF(F12="","",F12) -> No | G27: =IF(G12="","",G12) -> No | H27: =IF(H12="","",H12) -> 1 | I27: =IF(I12="","",I12) -> 0.3 | J27: =IF(J12="","",IF(ISNUMBER(J12),J12*'Conversion Factors'!$D$23,J12)) -> 5.4 | K27: =IF(K12="","",IF(ISNUMBER(K12),K12*'Conversion Factors'!$D$21,K12)) -> 5.4980612 | L27: =IF(K12="","",IF(ISNUMBER(K12),K12*'Conversion Factors'!$D$22,K12)) -> 560.64622
A28: =IF(A13="","",A13) -> 24F-1.8E SP_BAL | B28: =IF(B13="","",B13) -> Glulam | C28: =IF(C13="","",C13) -> NDS Table 5A | D28: =IF(D13="","",D13) -> 24F-1.8E_SP_BAL | E28: =IF(E13="","",E13) -> na | F28: =IF(F13="","",F13) -> No | G28: =IF(G13="","",G13) -> No | H28: =IF(H13="","",H13) -> 1 | I28: =IF(I13="","",I13) -> 0.3 | J28: =IF(J13="","",IF(ISNUMBER(J13),J13*'Conversion Factors'!$D$23,J13)) -> 5.4 | K28: =IF(K13="","",IF(ISNUMBER(K13),K13*'Conversion Factors'!$D$21,K13)) -> 5.4980612 | L28: =IF(K13="","",IF(ISNUMBER(K13),K13*'Conversion Factors'!$D$22,K13)) -> 560.64622
A29: =IF(A14="","",A14) -> 24F-1.8E SP_UNBAL | B29: =IF(B14="","",B14) -> Glulam | C29: =IF(C14="","",C14) -> NDS Table 5A | D29: =IF(D14="","",D14) -> 24F-1.8E_SP_UNBAL | E29: =IF(E14="","",E14) -> na | F29: =IF(F14="","",F14) -> No | G29: =IF(G14="","",G14) -> No | H29: =IF(H14="","",H14) -> 1 | I29: =IF(I14="","",I14) -> 0.3 | J29: =IF(J14="","",IF(ISNUMBER(J14),J14*'Conversion Factors'!$D$23,J14)) -> 5.4 | K29: =IF(K14="","",IF(ISNUMBER(K14),K14*'Conversion Factors'!$D$21,K14)) -> 5.4980612 | L29: =IF(K14="","",IF(ISNUMBER(K14),K14*'Conversion Factors'!$D$22,K14)) -> 560.64622
A30: =IF(A15="","",A15) -> LVL-PRL 1.5E_2250F | B30: =IF(B15="","",B15) -> Custom | C30: =IF(C15="","",C15) -> N/A | D30: =IF(D15="","",D15) -> LVL_PRL_1.5E_2250F | E30: =IF(E15="","",E15) -> na | F30: =IF(F15="","",F15) -> No | G30: =IF(G15="","",G15) -> No | H30: =IF(H15="","",H15) -> 1 | I30: =IF(I15="","",I15) -> 0.3 | J30: =IF(J15="","",IF(ISNUMBER(J15),J15*'Conversion Factors'!$D$23,J15)) -> 5.4 | K30: =IF(K15="","",IF(ISNUMBER(K15),K15*'Conversion Factors'!$D$21,K15)) -> 5.4980612 | L30: =IF(K15="","",IF(ISNUMBER(K15),K15*'Conversion Factors'!$D$22,K15)) -> 560.64622
A31: =IF(A16="","",A16) -> LVL-PRL 2.0E_2900F | B31: =IF(B16="","",B16) -> Custom | C31: =IF(C16="","",C16) -> N/A | D31: =IF(D16="","",D16) -> LVL_PRL_2.0E_2900F | E31: =IF(E16="","",E16) -> na | F31: =IF(F16="","",F16) -> No | G31: =IF(G16="","",G16) -> No | H31: =IF(H16="","",H16) -> 1 | I31: =IF(I16="","",I16) -> 0.3 | J31: =IF(J16="","",IF(ISNUMBER(J16),J16*'Conversion Factors'!$D$23,J16)) -> 5.4 | K31: =IF(K16="","",IF(ISNUMBER(K16),K16*'Conversion Factors'!$D$21,K16)) -> 5.4980612 | L31: =IF(K16="","",IF(ISNUMBER(K16),K16*'Conversion Factors'!$D$22,K16)) -> 560.64622
A33: Cm and Ci checkboxes are all unchecked in the source. Labels in rows 7 to 12 reconstructed from the Species column (truncated on screen).

Sheet Concrete
A1: Concrete Materials (RISA-3D)
A2: Source screenshot: Materials-SS-Concrete-TAB.png. Blue = transcribed input. Green = live formula check.
A3: Imperial (as shown in RISA): ksi, k/ft³, 1e-5/°F
A4: Label | B4: E [ksi] | C4: G [ksi] | D4: Nu | E4: Therm. Coeff. [1e-5/°F] | F4: Density [k/ft³] | G4: f'c [ksi] | H4: Lambda | I4: Flex Steel [ksi] | J4: Shear Steel [ksi] | L4: Solver check: G = E/(2(1+Nu)) [ksi] | M4: Diff vs table G
A5: Conc3000NW | B5: 3156 | C5: 1372 | D5: 0.15 | E5: 0.6 | F5: 0.145 | G5: 3 | H5: 1 | I5: 60 | J5: 60 | L5: =B5/(2*(1+D5)) -> 1372.1739 | M5: =IF(ISNUMBER(C5),(C5-L5)/L5,"n/a") -> -0.00012674271
A6: Conc3500NW | B6: 3409 | C6: 1482 | D6: 0.15 | E6: 0.6 | F6: 0.145 | G6: 3.5 | H6: 1 | I6: 60 | J6: 60 | L6: =B6/(2*(1+D6)) -> 1482.1739 | M6: =IF(ISNUMBER(C6),(C6-L6)/L6,"n/a") -> -0.00011733646
A7: Conc4000NW | B7: 3644 | C7: 1584 | D7: 0.15 | E7: 0.6 | F7: 0.145 | G7: 4 | H7: 1 | I7: 60 | J7: 60 | L7: =B7/(2*(1+D7)) -> 1584.3478 | M7: =IF(ISNUMBER(C7),(C7-L7)/L7,"n/a") -> -0.00021953897
A8: Conc3000LW | B8: 2085 | C8: 907 | D8: 0.15 | E8: 0.6 | F8: 0.11 | G8: 3 | H8: 0.75 | I8: 60 | J8: 60 | L8: =B8/(2*(1+D8)) -> 906.52174 | M8: =IF(ISNUMBER(C8),(C8-L8)/L8,"n/a") -> 0.00052757794
A9: Conc3500LW | B9: 2252 | C9: 979 | D9: 0.15 | E9: 0.6 | F9: 0.11 | G9: 3.5 | H9: 0.75 | I9: 60 | J9: 60 | L9: =B9/(2*(1+D9)) -> 979.13043 | M9: =IF(ISNUMBER(C9),(C9-L9)/L9,"n/a") -> -0.00013321492
A10: Conc4000LW | B10: 2408 | C10: 1047 | D10: 0.15 | E10: 0.6 | F10: 0.11 | G10: 4 | H10: 0.75 | I10: 60 | J10: 60 | L10: =B10/(2*(1+D10)) -> 1046.9565 | M10: =IF(ISNUMBER(C10),(C10-L10)/L10,"n/a") -> 4.1528239e-05
A12: Standard Metric (SI), computed by formula from the Imperial table above
A13: Label | B13: E [MPa] | C13: G [MPa] | D13: Nu | E13: Therm. Coeff. [1e-6/°C] | F13: Density [kN/m³] | G13: f'c [MPa] | H13: Lambda | I13: Flex Steel [MPa] | J13: Shear Steel [MPa] | K13: Mass Density [kg/m³] | L13: E [GPa]
A14: =IF(A5="","",A5) -> Conc3000NW | B14: =IF(B5="","",IF(ISNUMBER(B5),B5*'Conversion Factors'!$D$18,B5)) -> 21759.854 | C14: =IF(C5="","",IF(ISNUMBER(C5),C5*'Conversion Factors'!$D$18,C5)) -> 9459.607 | D14: =IF(D5="","",D5) -> 0.15 | E14: =IF(E5="","",IF(ISNUMBER(E5),E5*'Conversion Factors'!$D$23,E5)) -> 10.8 | F14: =IF(F5="","",IF(ISNUMBER(F5),F5*'Conversion Factors'!$D$21,F5)) -> 22.777682 | G14: =IF(G5="","",IF(ISNUMBER(G5),G5*'Conversion Factors'!$D$18,G5)) -> 20.684272 | H14: =IF(H5="","",H5) -> 1 | I14: =IF(I5="","",IF(ISNUMBER(I5),I5*'Conversion Factors'!$D$18,I5)) -> 413.68544 | J14: =IF(J5="","",IF(ISNUMBER(J5),J5*'Conversion Factors'!$D$18,J5)) -> 413.68544 | K14: =IF(F5="","",IF(ISNUMBER(F5),F5*'Conversion Factors'!$D$22,F5)) -> 2322.6772 | L14: =IF(B5="","",IF(ISNUMBER(B5),B5*'Conversion Factors'!$D$18/1000,B5)) -> 21.759854
A15: =IF(A6="","",A6) -> Conc3500NW | B15: =IF(B6="","",IF(ISNUMBER(B6),B6*'Conversion Factors'!$D$18,B6)) -> 23504.228 | C15: =IF(C6="","",IF(ISNUMBER(C6),C6*'Conversion Factors'!$D$18,C6)) -> 10218.03 | D15: =IF(D6="","",D6) -> 0.15 | E15: =IF(E6="","",IF(ISNUMBER(E6),E6*'Conversion Factors'!$D$23,E6)) -> 10.8 | F15: =IF(F6="","",IF(ISNUMBER(F6),F6*'Conversion Factors'!$D$21,F6)) -> 22.777682 | G15: =IF(G6="","",IF(ISNUMBER(G6),G6*'Conversion Factors'!$D$18,G6)) -> 24.131651 | H15: =IF(H6="","",H6) -> 1 | I15: =IF(I6="","",IF(ISNUMBER(I6),I6*'Conversion Factors'!$D$18,I6)) -> 413.68544 | J15: =IF(J6="","",IF(ISNUMBER(J6),J6*'Conversion Factors'!$D$18,J6)) -> 413.68544 | K15: =IF(F6="","",IF(ISNUMBER(F6),F6*'Conversion Factors'!$D$22,F6)) -> 2322.6772 | L15: =IF(B6="","",IF(ISNUMBER(B6),B6*'Conversion Factors'!$D$18/1000,B6)) -> 23.504228
A16: =IF(A7="","",A7) -> Conc4000NW | B16: =IF(B7="","",IF(ISNUMBER(B7),B7*'Conversion Factors'!$D$18,B7)) -> 25124.496 | C16: =IF(C7="","",IF(ISNUMBER(C7),C7*'Conversion Factors'!$D$18,C7)) -> 10921.296 | D16: =IF(D7="","",D7) -> 0.15 | E16: =IF(E7="","",IF(ISNUMBER(E7),E7*'Conversion Factors'!$D$23,E7)) -> 10.8 | F16: =IF(F7="","",IF(ISNUMBER(F7),F7*'Conversion Factors'!$D$21,F7)) -> 22.777682 | G16: =IF(G7="","",IF(ISNUMBER(G7),G7*'Conversion Factors'!$D$18,G7)) -> 27.579029 | H16: =IF(H7="","",H7) -> 1 | I16: =IF(I7="","",IF(ISNUMBER(I7),I7*'Conversion Factors'!$D$18,I7)) -> 413.68544 | J16: =IF(J7="","",IF(ISNUMBER(J7),J7*'Conversion Factors'!$D$18,J7)) -> 413.68544 | K16: =IF(F7="","",IF(ISNUMBER(F7),F7*'Conversion Factors'!$D$22,F7)) -> 2322.6772 | L16: =IF(B7="","",IF(ISNUMBER(B7),B7*'Conversion Factors'!$D$18/1000,B7)) -> 25.124496
A17: =IF(A8="","",A8) -> Conc3000LW | B17: =IF(B8="","",IF(ISNUMBER(B8),B8*'Conversion Factors'!$D$18,B8)) -> 14375.569 | C17: =IF(C8="","",IF(ISNUMBER(C8),C8*'Conversion Factors'!$D$18,C8)) -> 6253.5449 | D17: =IF(D8="","",D8) -> 0.15 | E17: =IF(E8="","",IF(ISNUMBER(E8),E8*'Conversion Factors'!$D$23,E8)) -> 10.8 | F17: =IF(F8="","",IF(ISNUMBER(F8),F8*'Conversion Factors'!$D$21,F8)) -> 17.279621 | G17: =IF(G8="","",IF(ISNUMBER(G8),G8*'Conversion Factors'!$D$18,G8)) -> 20.684272 | H17: =IF(H8="","",H8) -> 0.75 | I17: =IF(I8="","",IF(ISNUMBER(I8),I8*'Conversion Factors'!$D$18,I8)) -> 413.68544 | J17: =IF(J8="","",IF(ISNUMBER(J8),J8*'Conversion Factors'!$D$18,J8)) -> 413.68544 | K17: =IF(F8="","",IF(ISNUMBER(F8),F8*'Conversion Factors'!$D$22,F8)) -> 1762.031 | L17: =IF(B8="","",IF(ISNUMBER(B8),B8*'Conversion Factors'!$D$18/1000,B8)) -> 14.375569
A18: =IF(A9="","",A9) -> Conc3500LW | B18: =IF(B9="","",IF(ISNUMBER(B9),B9*'Conversion Factors'!$D$18,B9)) -> 15526.993 | C18: =IF(C9="","",IF(ISNUMBER(C9),C9*'Conversion Factors'!$D$18,C9)) -> 6749.9674 | D18: =IF(D9="","",D9) -> 0.15 | E18: =IF(E9="","",IF(ISNUMBER(E9),E9*'Conversion Factors'!$D$23,E9)) -> 10.8 | F18: =IF(F9="","",IF(ISNUMBER(F9),F9*'Conversion Factors'!$D$21,F9)) -> 17.279621 | G18: =IF(G9="","",IF(ISNUMBER(G9),G9*'Conversion Factors'!$D$18,G9)) -> 24.131651 | H18: =IF(H9="","",H9) -> 0.75 | I18: =IF(I9="","",IF(ISNUMBER(I9),I9*'Conversion Factors'!$D$18,I9)) -> 413.68544 | J18: =IF(J9="","",IF(ISNUMBER(J9),J9*'Conversion Factors'!$D$18,J9)) -> 413.68544 | K18: =IF(F9="","",IF(ISNUMBER(F9),F9*'Conversion Factors'!$D$22,F9)) -> 1762.031 | L18: =IF(B9="","",IF(ISNUMBER(B9),B9*'Conversion Factors'!$D$18/1000,B9)) -> 15.526993
A19: =IF(A10="","",A10) -> Conc4000LW | B19: =IF(B10="","",IF(ISNUMBER(B10),B10*'Conversion Factors'!$D$18,B10)) -> 16602.576 | C19: =IF(C10="","",IF(ISNUMBER(C10),C10*'Conversion Factors'!$D$18,C10)) -> 7218.8109 | D19: =IF(D10="","",D10) -> 0.15 | E19: =IF(E10="","",IF(ISNUMBER(E10),E10*'Conversion Factors'!$D$23,E10)) -> 10.8 | F19: =IF(F10="","",IF(ISNUMBER(F10),F10*'Conversion Factors'!$D$21,F10)) -> 17.279621 | G19: =IF(G10="","",IF(ISNUMBER(G10),G10*'Conversion Factors'!$D$18,G10)) -> 27.579029 | H19: =IF(H10="","",H10) -> 0.75 | I19: =IF(I10="","",IF(ISNUMBER(I10),I10*'Conversion Factors'!$D$18,I10)) -> 413.68544 | J19: =IF(J10="","",IF(ISNUMBER(J10),J10*'Conversion Factors'!$D$18,J10)) -> 413.68544 | K19: =IF(F10="","",IF(ISNUMBER(F10),F10*'Conversion Factors'!$D$22,F10)) -> 1762.031 | L19: =IF(B10="","",IF(ISNUMBER(B10),B10*'Conversion Factors'!$D$18/1000,B10)) -> 16.602576

Sheet Masonry
A1: Masonry Materials (RISA-3D)
A2: Source screenshot: Materials-SS-Masonry-TAB.png. Blue = transcribed input. Green = live formula check.
A3: Imperial (as shown in RISA): ksi, k/ft³, 1e-5/°F
A4: Label | B4: E [ksi] | C4: G [ksi] | D4: Nu | E4: Therm. Coeff. [1e-5/°F] | F4: Self Weight [k/ft³] | G4: f'm [ksi] | H4: Flex Steel [ksi] | I4: Shear Steel [ksi] | K4: Solver check: G = E/(2(1+Nu)) [ksi] | L4: Diff vs table G
A5: Concrete Matl | B5: 1350 | C5: 540 | D5: 0.25 | E5: 0.6 | F5: Custom | G5: 1.5 | H5: 60 | I5: 60 | K5: =B5/(2*(1+D5)) -> 540 | L5: =IF(ISNUMBER(C5),(C5-K5)/K5,"n/a") -> 0
A6: Clay Matl | B6: 1050 | C6: 420 | D6: 0.25 | E6: 0.6 | F6: Custom | G6: 1.5 | H6: 60 | I6: 60 | K6: =B6/(2*(1+D6)) -> 420 | L6: =IF(ISNUMBER(C6),(C6-K6)/K6,"n/a") -> 0
A8: Standard Metric (SI), computed by formula from the Imperial table above
A9: Label | B9: E [MPa] | C9: G [MPa] | D9: Nu | E9: Therm. Coeff. [1e-6/°C] | F9: Self Weight [kN/m³] | G9: f'm [MPa] | H9: Flex Steel [MPa] | I9: Shear Steel [MPa] | J9: Mass Density [kg/m³] | K9: E [GPa]
A10: =IF(A5="","",A5) -> Concrete Matl | B10: =IF(B5="","",IF(ISNUMBER(B5),B5*'Conversion Factors'!$D$18,B5)) -> 9307.9223 | C10: =IF(C5="","",IF(ISNUMBER(C5),C5*'Conversion Factors'!$D$18,C5)) -> 3723.1689 | D10: =IF(D5="","",D5) -> 0.25 | E10: =IF(E5="","",IF(ISNUMBER(E5),E5*'Conversion Factors'!$D$23,E5)) -> 10.8 | F10: =IF(F5="","",IF(ISNUMBER(F5),F5*'Conversion Factors'!$D$21,F5)) -> Custom | G10: =IF(G5="","",IF(ISNUMBER(G5),G5*'Conversion Factors'!$D$18,G5)) -> 10.342136 | H10: =IF(H5="","",IF(ISNUMBER(H5),H5*'Conversion Factors'!$D$18,H5)) -> 413.68544 | I10: =IF(I5="","",IF(ISNUMBER(I5),I5*'Conversion Factors'!$D$18,I5)) -> 413.68544 | J10: =IF(F5="","",IF(ISNUMBER(F5),F5*'Conversion Factors'!$D$22,F5)) -> Custom | K10: =IF(B5="","",IF(ISNUMBER(B5),B5*'Conversion Factors'!$D$18/1000,B5)) -> 9.3079223
A11: =IF(A6="","",A6) -> Clay Matl | B11: =IF(B6="","",IF(ISNUMBER(B6),B6*'Conversion Factors'!$D$18,B6)) -> 7239.4952 | C11: =IF(C6="","",IF(ISNUMBER(C6),C6*'Conversion Factors'!$D$18,C6)) -> 2895.7981 | D11: =IF(D6="","",D6) -> 0.25 | E11: =IF(E6="","",IF(ISNUMBER(E6),E6*'Conversion Factors'!$D$23,E6)) -> 10.8 | F11: =IF(F6="","",IF(ISNUMBER(F6),F6*'Conversion Factors'!$D$21,F6)) -> Custom | G11: =IF(G6="","",IF(ISNUMBER(G6),G6*'Conversion Factors'!$D$18,G6)) -> 10.342136 | H11: =IF(H6="","",IF(ISNUMBER(H6),H6*'Conversion Factors'!$D$18,H6)) -> 413.68544 | I11: =IF(I6="","",IF(ISNUMBER(I6),I6*'Conversion Factors'!$D$18,I6)) -> 413.68544 | J11: =IF(F6="","",IF(ISNUMBER(F6),F6*'Conversion Factors'!$D$22,F6)) -> Custom | K11: =IF(B6="","",IF(ISNUMBER(B6),B6*'Conversion Factors'!$D$18/1000,B6)) -> 7.2394952
A14: Masonry Self Weight dialog (Masonry-Self-Weight-WND.png)
A15: Selected method | B15: Using Block and Grout Properties
A16: Block Material | B16: Conc 115 pcf
A17: Grout Weight | B17: 140 pcf
A18: Uniform Density alternative (not selected) [k/ft³] | B18: 0.08

Sheet Aluminum
A1: Aluminum Materials (RISA-3D)
A2: Source screenshot: Materials-SS-Aluminum-TAB.png. Blue = transcribed input. Green = live formula check.
A3: Imperial (as shown in RISA): ksi, k/ft³, 1e-5/°F
A4: Label | B4: E [ksi] | C4: G [ksi] | D4: Nu | E4: Therm. Coeff. [1e-5/°F] | F4: Density [k/ft³] | G4: Table B.4 | H4: kt | I4: Ftu [ksi] | J4: Fty [ksi] | K4: Fcy [ksi] | L4: Fsu [ksi] | M4: Ct | O4: Solver check: G = E/(2(1+Nu)) [ksi] | P4: Diff vs table G
A5: 3003-H14 | B5: 10100 | C5: 3787.5 | D5: 0.33 | E5: 1.3 | F5: 0.173 | G5: Table B.4-1 | H5: 1 | I5: 19 | J5: 16 | K5: 13 | L5: 12 | M5: 141 | O5: =B5/(2*(1+D5)) -> 3796.9925 | P5: =IF(ISNUMBER(C5),(C5-O5)/O5,"n/a") -> -0.0025
A6: 6061-T6 | B6: 10100 | C6: 3787.5 | D6: 0.33 | E6: 1.3 | F6: 0.173 | G6: Table B.4-2 | H6: 1 | I6: 38 | J6: 35 | K6: 35 | L6: 24 | M6: 141 | O6: =B6/(2*(1+D6)) -> 3796.9925 | P6: =IF(ISNUMBER(C6),(C6-O6)/O6,"n/a") -> -0.0025
A7: 6063-T5 | B7: 10100 | C7: 3787.5 | D7: 0.33 | E7: 1.3 | F7: 0.173 | G7: Table B.4-2 | H7: 1 | I7: 22 | J7: 16 | K7: 16 | L7: 13 | M7: 141 | O7: =B7/(2*(1+D7)) -> 3796.9925 | P7: =IF(ISNUMBER(C7),(C7-O7)/O7,"n/a") -> -0.0025
A8: 6063-T6 | B8: 10100 | C8: 3787.5 | D8: 0.33 | E8: 1.3 | F8: 0.173 | G8: Table B.4-2 | H8: 1 | I8: 30 | J8: 25 | K8: 25 | L8: 19 | M8: 141 | O8: =B8/(2*(1+D8)) -> 3796.9925 | P8: =IF(ISNUMBER(C8),(C8-O8)/O8,"n/a") -> -0.0025
A9: 5052-H34 | B9: 10200 | C9: 3787.5 | D9: 0.33 | E9: 1.3 | F9: 0.173 | G9: Table B.4-1 | H9: 1 | I9: 34 | J9: 26 | K9: 24 | L9: 20 | M9: 141 | O9: =B9/(2*(1+D9)) -> 3834.5865 | P9: =IF(ISNUMBER(C9),(C9-O9)/O9,"n/a") -> -0.012279412
A10: 6061-T6 (welded) | B10: 10100 | C10: 3787.5 | D10: 0.33 | E10: 1.3 | F10: 0.173 | G10: Table B.4-2 | H10: 1 | I10: 24 | J10: 15 | K10: 15 | L10: 15 | M10: 141 | O10: =B10/(2*(1+D10)) -> 3796.9925 | P10: =IF(ISNUMBER(C10),(C10-O10)/O10,"n/a") -> -0.0025
A12: Standard Metric (SI), computed by formula from the Imperial table above
A13: Label | B13: E [MPa] | C13: G [MPa] | D13: Nu | E13: Therm. Coeff. [1e-6/°C] | F13: Density [kN/m³] | G13: Table B.4 | H13: kt | I13: Ftu [MPa] | J13: Fty [MPa] | K13: Fcy [MPa] | L13: Fsu [MPa] | M13: Ct | N13: Mass Density [kg/m³] | O13: E [GPa]
A14: =IF(A5="","",A5) -> 3003-H14 | B14: =IF(B5="","",IF(ISNUMBER(B5),B5*'Conversion Factors'!$D$18,B5)) -> 69637.049 | C14: =IF(C5="","",IF(ISNUMBER(C5),C5*'Conversion Factors'!$D$18,C5)) -> 26113.893 | D14: =IF(D5="","",D5) -> 0.33 | E14: =IF(E5="","",IF(ISNUMBER(E5),E5*'Conversion Factors'!$D$23,E5)) -> 23.4 | F14: =IF(F5="","",IF(ISNUMBER(F5),F5*'Conversion Factors'!$D$21,F5)) -> 27.176131 | G14: =IF(G5="","",G5) -> Table B.4-1 | H14: =IF(H5="","",H5) -> 1 | I14: =IF(I5="","",IF(ISNUMBER(I5),I5*'Conversion Factors'!$D$18,I5)) -> 131.00039 | J14: =IF(J5="","",IF(ISNUMBER(J5),J5*'Conversion Factors'!$D$18,J5)) -> 110.31612 | K14: =IF(K5="","",IF(ISNUMBER(K5),K5*'Conversion Factors'!$D$18,K5)) -> 89.631845 | L14: =IF(L5="","",IF(ISNUMBER(L5),L5*'Conversion Factors'!$D$18,L5)) -> 82.737088 | M14: =IF(M5="","",M5) -> 141 | N14: =IF(F5="","",IF(ISNUMBER(F5),F5*'Conversion Factors'!$D$22,F5)) -> 2771.1942 | O14: =IF(B5="","",IF(ISNUMBER(B5),B5*'Conversion Factors'!$D$18/1000,B5)) -> 69.637049
A15: =IF(A6="","",A6) -> 6061-T6 | B15: =IF(B6="","",IF(ISNUMBER(B6),B6*'Conversion Factors'!$D$18,B6)) -> 69637.049 | C15: =IF(C6="","",IF(ISNUMBER(C6),C6*'Conversion Factors'!$D$18,C6)) -> 26113.893 | D15: =IF(D6="","",D6) -> 0.33 | E15: =IF(E6="","",IF(ISNUMBER(E6),E6*'Conversion Factors'!$D$23,E6)) -> 23.4 | F15: =IF(F6="","",IF(ISNUMBER(F6),F6*'Conversion Factors'!$D$21,F6)) -> 27.176131 | G15: =IF(G6="","",G6) -> Table B.4-2 | H15: =IF(H6="","",H6) -> 1 | I15: =IF(I6="","",IF(ISNUMBER(I6),I6*'Conversion Factors'!$D$18,I6)) -> 262.00078 | J15: =IF(J6="","",IF(ISNUMBER(J6),J6*'Conversion Factors'!$D$18,J6)) -> 241.31651 | K15: =IF(K6="","",IF(ISNUMBER(K6),K6*'Conversion Factors'!$D$18,K6)) -> 241.31651 | L15: =IF(L6="","",IF(ISNUMBER(L6),L6*'Conversion Factors'!$D$18,L6)) -> 165.47418 | M15: =IF(M6="","",M6) -> 141 | N15: =IF(F6="","",IF(ISNUMBER(F6),F6*'Conversion Factors'!$D$22,F6)) -> 2771.1942 | O15: =IF(B6="","",IF(ISNUMBER(B6),B6*'Conversion Factors'!$D$18/1000,B6)) -> 69.637049
A16: =IF(A7="","",A7) -> 6063-T5 | B16: =IF(B7="","",IF(ISNUMBER(B7),B7*'Conversion Factors'!$D$18,B7)) -> 69637.049 | C16: =IF(C7="","",IF(ISNUMBER(C7),C7*'Conversion Factors'!$D$18,C7)) -> 26113.893 | D16: =IF(D7="","",D7) -> 0.33 | E16: =IF(E7="","",IF(ISNUMBER(E7),E7*'Conversion Factors'!$D$23,E7)) -> 23.4 | F16: =IF(F7="","",IF(ISNUMBER(F7),F7*'Conversion Factors'!$D$21,F7)) -> 27.176131 | G16: =IF(G7="","",G7) -> Table B.4-2 | H16: =IF(H7="","",H7) -> 1 | I16: =IF(I7="","",IF(ISNUMBER(I7),I7*'Conversion Factors'!$D$18,I7)) -> 151.68466 | J16: =IF(J7="","",IF(ISNUMBER(J7),J7*'Conversion Factors'!$D$18,J7)) -> 110.31612 | K16: =IF(K7="","",IF(ISNUMBER(K7),K7*'Conversion Factors'!$D$18,K7)) -> 110.31612 | L16: =IF(L7="","",IF(ISNUMBER(L7),L7*'Conversion Factors'!$D$18,L7)) -> 89.631845 | M16: =IF(M7="","",M7) -> 141 | N16: =IF(F7="","",IF(ISNUMBER(F7),F7*'Conversion Factors'!$D$22,F7)) -> 2771.1942 | O16: =IF(B7="","",IF(ISNUMBER(B7),B7*'Conversion Factors'!$D$18/1000,B7)) -> 69.637049
A17: =IF(A8="","",A8) -> 6063-T6 | B17: =IF(B8="","",IF(ISNUMBER(B8),B8*'Conversion Factors'!$D$18,B8)) -> 69637.049 | C17: =IF(C8="","",IF(ISNUMBER(C8),C8*'Conversion Factors'!$D$18,C8)) -> 26113.893 | D17: =IF(D8="","",D8) -> 0.33 | E17: =IF(E8="","",IF(ISNUMBER(E8),E8*'Conversion Factors'!$D$23,E8)) -> 23.4 | F17: =IF(F8="","",IF(ISNUMBER(F8),F8*'Conversion Factors'!$D$21,F8)) -> 27.176131 | G17: =IF(G8="","",G8) -> Table B.4-2 | H17: =IF(H8="","",H8) -> 1 | I17: =IF(I8="","",IF(ISNUMBER(I8),I8*'Conversion Factors'!$D$18,I8)) -> 206.84272 | J17: =IF(J8="","",IF(ISNUMBER(J8),J8*'Conversion Factors'!$D$18,J8)) -> 172.36893 | K17: =IF(K8="","",IF(ISNUMBER(K8),K8*'Conversion Factors'!$D$18,K8)) -> 172.36893 | L17: =IF(L8="","",IF(ISNUMBER(L8),L8*'Conversion Factors'!$D$18,L8)) -> 131.00039 | M17: =IF(M8="","",M8) -> 141 | N17: =IF(F8="","",IF(ISNUMBER(F8),F8*'Conversion Factors'!$D$22,F8)) -> 2771.1942 | O17: =IF(B8="","",IF(ISNUMBER(B8),B8*'Conversion Factors'!$D$18/1000,B8)) -> 69.637049
A18: =IF(A9="","",A9) -> 5052-H34 | B18: =IF(B9="","",IF(ISNUMBER(B9),B9*'Conversion Factors'!$D$18,B9)) -> 70326.524 | C18: =IF(C9="","",IF(ISNUMBER(C9),C9*'Conversion Factors'!$D$18,C9)) -> 26113.893 | D18: =IF(D9="","",D9) -> 0.33 | E18: =IF(E9="","",IF(ISNUMBER(E9),E9*'Conversion Factors'!$D$23,E9)) -> 23.4 | F18: =IF(F9="","",IF(ISNUMBER(F9),F9*'Conversion Factors'!$D$21,F9)) -> 27.176131 | G18: =IF(G9="","",G9) -> Table B.4-1 | H18: =IF(H9="","",H9) -> 1 | I18: =IF(I9="","",IF(ISNUMBER(I9),I9*'Conversion Factors'!$D$18,I9)) -> 234.42175 | J18: =IF(J9="","",IF(ISNUMBER(J9),J9*'Conversion Factors'!$D$18,J9)) -> 179.26369 | K18: =IF(K9="","",IF(ISNUMBER(K9),K9*'Conversion Factors'!$D$18,K9)) -> 165.47418 | L18: =IF(L9="","",IF(ISNUMBER(L9),L9*'Conversion Factors'!$D$18,L9)) -> 137.89515 | M18: =IF(M9="","",M9) -> 141 | N18: =IF(F9="","",IF(ISNUMBER(F9),F9*'Conversion Factors'!$D$22,F9)) -> 2771.1942 | O18: =IF(B9="","",IF(ISNUMBER(B9),B9*'Conversion Factors'!$D$18/1000,B9)) -> 70.326524
A19: =IF(A10="","",A10) -> 6061-T6 (welded) | B19: =IF(B10="","",IF(ISNUMBER(B10),B10*'Conversion Factors'!$D$18,B10)) -> 69637.049 | C19: =IF(C10="","",IF(ISNUMBER(C10),C10*'Conversion Factors'!$D$18,C10)) -> 26113.893 | D19: =IF(D10="","",D10) -> 0.33 | E19: =IF(E10="","",IF(ISNUMBER(E10),E10*'Conversion Factors'!$D$23,E10)) -> 23.4 | F19: =IF(F10="","",IF(ISNUMBER(F10),F10*'Conversion Factors'!$D$21,F10)) -> 27.176131 | G19: =IF(G10="","",G10) -> Table B.4-2 | H19: =IF(H10="","",H10) -> 1 | I19: =IF(I10="","",IF(ISNUMBER(I10),I10*'Conversion Factors'!$D$18,I10)) -> 165.47418 | J19: =IF(J10="","",IF(ISNUMBER(J10),J10*'Conversion Factors'!$D$18,J10)) -> 103.42136 | K19: =IF(K10="","",IF(ISNUMBER(K10),K10*'Conversion Factors'!$D$18,K10)) -> 103.42136 | L19: =IF(L10="","",IF(ISNUMBER(L10),L10*'Conversion Factors'!$D$18,L10)) -> 103.42136 | M19: =IF(M10="","",M10) -> 141 | N19: =IF(F10="","",IF(ISNUMBER(F10),F10*'Conversion Factors'!$D$22,F10)) -> 2771.1942 | O19: =IF(B10="","",IF(ISNUMBER(B10),B10*'Conversion Factors'!$D$18/1000,B10)) -> 69.637049
A21: Row 6 label truncated on screen ('6061-T6...'); strengths match welded 6061-T6.

Sheet Stainless
A1: Stainless Materials (RISA-3D)
A2: Source screenshot: Materials-SS-Stainless-TAB.png. Blue = transcribed input. Green = live formula check.
A3: Imperial (as shown in RISA): ksi, k/ft³, 1e-5/°F
A4: Label | B4: E [ksi] | C4: G [ksi] | D4: Nu | E4: Therm. Coeff. [1e-5/°F] | F4: Density [k/ft³] | G4: n | H4: Yield [ksi] | I4: Fu [ksi] | K4: Solver check: G = E/(2(1+Nu)) [ksi] | L4: Diff vs table G
A5: SS1 | B5: 193100 | C5: 74325.484 | D5: 0.3 | E5: 1.674 | F5: 8.009 | G5: 5.6 | H5: 206.843 | I5: 517.107 | K5: =B5/(2*(1+D5)) -> 74269.231 | L5: =IF(ISNUMBER(C5),(C5-K5)/K5,"n/a") -> 0.0007574231
A7: Standard Metric (SI), computed by formula from the Imperial table above
A8: Label | B8: E [MPa] | C8: G [MPa] | D8: Nu | E8: Therm. Coeff. [1e-6/°C] | F8: Density [kN/m³] | G8: n | H8: Yield [MPa] | I8: Fu [MPa] | J8: Mass Density [kg/m³] | K8: E [GPa]
A9: =IF(A5="","",A5) -> SS1 | B9: =IF(B5="","",IF(ISNUMBER(B5),B5*'Conversion Factors'!$D$18,B5)) -> 1331377.6 | C9: =IF(C5="","",IF(ISNUMBER(C5),C5*'Conversion Factors'!$D$18,C5)) -> 512456.17 | D9: =IF(D5="","",D5) -> 0.3 | E9: =IF(E5="","",IF(ISNUMBER(E5),E5*'Conversion Factors'!$D$23,E5)) -> 30.132 | F9: =IF(F5="","",IF(ISNUMBER(F5),F5*'Conversion Factors'!$D$21,F5)) -> 1258.1135 | G9: =IF(G5="","",G5) -> 5.6 | H9: =IF(H5="","",IF(ISNUMBER(H5),H5*'Conversion Factors'!$D$18,H5)) -> 1426.1323 | I9: =IF(I5="","",IF(ISNUMBER(I5),I5*'Conversion Factors'!$D$18,I5)) -> 3565.3273 | J9: =IF(F5="","",IF(ISNUMBER(F5),F5*'Conversion Factors'!$D$22,F5)) -> 128291.87 | K9: =IF(B5="","",IF(ISNUMBER(B5),B5*'Conversion Factors'!$D$18/1000,B5)) -> 1331.3776
A11: Values as displayed. Magnitudes are SI (MPa) under ksi headers: 206.843 MPa = 30 ksi, 517.107 MPa = 75 ksi, 193,100 MPa = 28,000 ksi. Verify RISA unit setting before use.

Sheet General
A1: General Materials (RISA-3D)
A2: Source screenshot: Materials-SS-General-TAB.png. Blue = transcribed input. Green = live formula check.
A3: Imperial (as shown in RISA): ksi, k/ft³, 1e-5/°F
A4: Label | B4: E [ksi] | C4: G [ksi] | D4: Nu | E4: Therm. Coeff. [1e-5/°F] | F4: Density [k/ft³] | G4: Plate Methodology | I4: Solver check: G = E/(2(1+Nu)) [ksi] | J4: Diff vs table G
A5: gen_Conc3NW | B5: 3155 | C5: 1372 | D5: 0.15 | E5: 0.6 | F5: 0.145 | G5: Isotropic | I5: =B5/(2*(1+D5)) -> 1371.7391 | J5: =IF(ISNUMBER(C5),(C5-I5)/I5,"n/a") -> 0.00019017433
A6: gen_Conc4NW | B6: 3644 | C6: 1584 | D6: 0.15 | E6: 0.6 | F6: 0.145 | G6: Isotropic | I6: =B6/(2*(1+D6)) -> 1584.3478 | J6: =IF(ISNUMBER(C6),(C6-I6)/I6,"n/a") -> -0.00021953897
A7: gen_Conc3LW | B7: 2085 | C7: 906 | D7: 0.15 | E7: 0.6 | F7: 0.11 | G7: Isotropic | I7: =B7/(2*(1+D7)) -> 906.52174 | J7: =IF(ISNUMBER(C7),(C7-I7)/I7,"n/a") -> -0.00057553957
A8: gen_Conc4LW | B8: 2408 | C8: 1047 | D8: 0.15 | E8: 0.6 | F8: 0.11 | G8: Isotropic | I8: =B8/(2*(1+D8)) -> 1046.9565 | J8: =IF(ISNUMBER(C8),(C8-I8)/I8,"n/a") -> 4.1528239e-05
A9: gen_Alum | B9: 10600 | C9: 4077 | D9: 0.3 | E9: 1.29 | F9: 0.173 | G9: Isotropic | I9: =B9/(2*(1+D9)) -> 4076.9231 | J9: =IF(ISNUMBER(C9),(C9-I9)/I9,"n/a") -> 1.8867925e-05
A10: gen_Steel | B10: 29000 | C10: 11154 | D10: 0.3 | E10: 0.65 | F10: 0.49 | G10: Isotropic | I10: =B10/(2*(1+D10)) -> 11153.846 | J10: =IF(ISNUMBER(C10),(C10-I10)/I10,"n/a") -> 1.3793103e-05
A11: RIGID | B11: 1000000 | D11: 0.3 | E11: 0 | F11: 0 | G11: Isotropic | I11: =B11/(2*(1+D11)) -> 384615.38 | J11: =IF(ISNUMBER(C11),(C11-I11)/I11,"n/a") -> n/a
A13: Standard Metric (SI), computed by formula from the Imperial table above
A14: Label | B14: E [MPa] | C14: G [MPa] | D14: Nu | E14: Therm. Coeff. [1e-6/°C] | F14: Density [kN/m³] | G14: Plate Methodology | H14: Mass Density [kg/m³] | I14: E [GPa]
A15: =IF(A5="","",A5) -> gen_Conc3NW | B15: =IF(B5="","",IF(ISNUMBER(B5),B5*'Conversion Factors'!$D$18,B5)) -> 21752.959 | C15: =IF(C5="","",IF(ISNUMBER(C5),C5*'Conversion Factors'!$D$18,C5)) -> 9459.607 | D15: =IF(D5="","",D5) -> 0.15 | E15: =IF(E5="","",IF(ISNUMBER(E5),E5*'Conversion Factors'!$D$23,E5)) -> 10.8 | F15: =IF(F5="","",IF(ISNUMBER(F5),F5*'Conversion Factors'!$D$21,F5)) -> 22.777682 | G15: =IF(G5="","",G5) -> Isotropic | H15: =IF(F5="","",IF(ISNUMBER(F5),F5*'Conversion Factors'!$D$22,F5)) -> 2322.6772 | I15: =IF(B5="","",IF(ISNUMBER(B5),B5*'Conversion Factors'!$D$18/1000,B5)) -> 21.752959
A16: =IF(A6="","",A6) -> gen_Conc4NW | B16: =IF(B6="","",IF(ISNUMBER(B6),B6*'Conversion Factors'!$D$18,B6)) -> 25124.496 | C16: =IF(C6="","",IF(ISNUMBER(C6),C6*'Conversion Factors'!$D$18,C6)) -> 10921.296 | D16: =IF(D6="","",D6) -> 0.15 | E16: =IF(E6="","",IF(ISNUMBER(E6),E6*'Conversion Factors'!$D$23,E6)) -> 10.8 | F16: =IF(F6="","",IF(ISNUMBER(F6),F6*'Conversion Factors'!$D$21,F6)) -> 22.777682 | G16: =IF(G6="","",G6) -> Isotropic | H16: =IF(F6="","",IF(ISNUMBER(F6),F6*'Conversion Factors'!$D$22,F6)) -> 2322.6772 | I16: =IF(B6="","",IF(ISNUMBER(B6),B6*'Conversion Factors'!$D$18/1000,B6)) -> 25.124496
A17: =IF(A7="","",A7) -> gen_Conc3LW | B17: =IF(B7="","",IF(ISNUMBER(B7),B7*'Conversion Factors'!$D$18,B7)) -> 14375.569 | C17: =IF(C7="","",IF(ISNUMBER(C7),C7*'Conversion Factors'!$D$18,C7)) -> 6246.6501 | D17: =IF(D7="","",D7) -> 0.15 | E17: =IF(E7="","",IF(ISNUMBER(E7),E7*'Conversion Factors'!$D$23,E7)) -> 10.8 | F17: =IF(F7="","",IF(ISNUMBER(F7),F7*'Conversion Factors'!$D$21,F7)) -> 17.279621 | G17: =IF(G7="","",G7) -> Isotropic | H17: =IF(F7="","",IF(ISNUMBER(F7),F7*'Conversion Factors'!$D$22,F7)) -> 1762.031 | I17: =IF(B7="","",IF(ISNUMBER(B7),B7*'Conversion Factors'!$D$18/1000,B7)) -> 14.375569
A18: =IF(A8="","",A8) -> gen_Conc4LW | B18: =IF(B8="","",IF(ISNUMBER(B8),B8*'Conversion Factors'!$D$18,B8)) -> 16602.576 | C18: =IF(C8="","",IF(ISNUMBER(C8),C8*'Conversion Factors'!$D$18,C8)) -> 7218.8109 | D18: =IF(D8="","",D8) -> 0.15 | E18: =IF(E8="","",IF(ISNUMBER(E8),E8*'Conversion Factors'!$D$23,E8)) -> 10.8 | F18: =IF(F8="","",IF(ISNUMBER(F8),F8*'Conversion Factors'!$D$21,F8)) -> 17.279621 | G18: =IF(G8="","",G8) -> Isotropic | H18: =IF(F8="","",IF(ISNUMBER(F8),F8*'Conversion Factors'!$D$22,F8)) -> 1762.031 | I18: =IF(B8="","",IF(ISNUMBER(B8),B8*'Conversion Factors'!$D$18/1000,B8)) -> 16.602576
A19: =IF(A9="","",A9) -> gen_Alum | B19: =IF(B9="","",IF(ISNUMBER(B9),B9*'Conversion Factors'!$D$18,B9)) -> 73084.427 | C19: =IF(C9="","",IF(ISNUMBER(C9),C9*'Conversion Factors'!$D$18,C9)) -> 28109.925 | D19: =IF(D9="","",D9) -> 0.3 | E19: =IF(E9="","",IF(ISNUMBER(E9),E9*'Conversion Factors'!$D$23,E9)) -> 23.22 | F19: =IF(F9="","",IF(ISNUMBER(F9),F9*'Conversion Factors'!$D$21,F9)) -> 27.176131 | G19: =IF(G9="","",G9) -> Isotropic | H19: =IF(F9="","",IF(ISNUMBER(F9),F9*'Conversion Factors'!$D$22,F9)) -> 2771.1942 | I19: =IF(B9="","",IF(ISNUMBER(B9),B9*'Conversion Factors'!$D$18/1000,B9)) -> 73.084427
A20: =IF(A10="","",A10) -> gen_Steel | B20: =IF(B10="","",IF(ISNUMBER(B10),B10*'Conversion Factors'!$D$18,B10)) -> 199947.96 | C20: =IF(C10="","",IF(ISNUMBER(C10),C10*'Conversion Factors'!$D$18,C10)) -> 76904.123 | D20: =IF(D10="","",D10) -> 0.3 | E20: =IF(E10="","",IF(ISNUMBER(E10),E10*'Conversion Factors'!$D$23,E10)) -> 11.7 | F20: =IF(F10="","",IF(ISNUMBER(F10),F10*'Conversion Factors'!$D$21,F10)) -> 76.972857 | G20: =IF(G10="","",G10) -> Isotropic | H20: =IF(F10="","",IF(ISNUMBER(F10),F10*'Conversion Factors'!$D$22,F10)) -> 7849.0471 | I20: =IF(B10="","",IF(ISNUMBER(B10),B10*'Conversion Factors'!$D$18/1000,B10)) -> 199.94796
A21: =IF(A11="","",A11) -> RIGID | B21: =IF(B11="","",IF(ISNUMBER(B11),B11*'Conversion Factors'!$D$18,B11)) -> 6894757.3 | C21: =IF(C11="","",IF(ISNUMBER(C11),C11*'Conversion Factors'!$D$18,C11)) | D21: =IF(D11="","",D11) -> 0.3 | E21: =IF(E11="","",IF(ISNUMBER(E11),E11*'Conversion Factors'!$D$23,E11)) -> 0 | F21: =IF(F11="","",IF(ISNUMBER(F11),F11*'Conversion Factors'!$D$21,F11)) -> 0 | G21: =IF(G11="","",G11) -> Isotropic | H21: =IF(F11="","",IF(ISNUMBER(F11),F11*'Conversion Factors'!$D$22,F11)) -> 0 | I21: =IF(B11="","",IF(ISNUMBER(B11),B11*'Conversion Factors'!$D$18/1000,B11)) -> 6894.7573
A23: RIGID: G left blank in RISA; use for stiff links only. E shown as 1e+6 ksi.

Sheet All Materials
A1: All Materials, flat table for the solver
A2: Blue = transcribed input (Imperial, columns C to I). Black = formula (Standard Metric, columns J to P, using the Conversion Factors sheet).
A4: Category | B4: Label | C4: E [ksi] | D4: G [ksi] | E4: Nu | F4: Therm. Coeff. [1e-5/°F] | G4: Density [k/ft³] | H4: Yield / f'c / f'm [ksi] | I4: Fu [ksi] | J4: E [MPa] | K4: G [MPa] | L4: Therm. Coeff. [1e-6/°C] | M4: Density [kN/m³] | N4: Mass Density [kg/m³] | O4: Yield / f'c / f'm [MPa] | P4: Fu [MPa]
A5: Hot Rolled | B5: A36 Gr.36 | C5: 29000 | D5: 11154 | E5: 0.3 | F5: 0.65 | G5: 0.49 | H5: 36 | I5: 58 | J5: =IF(ISNUMBER(C5),C5*'Conversion Factors'!$D$18,"") -> 199947.96 | K5: =IF(ISNUMBER(D5),D5*'Conversion Factors'!$D$18,"") -> 76904.123 | L5: =IF(ISNUMBER(F5),F5*'Conversion Factors'!$D$23,"") -> 11.7 | M5: =IF(ISNUMBER(G5),G5*'Conversion Factors'!$D$21,"") -> 76.972857 | N5: =IF(ISNUMBER(G5),G5*'Conversion Factors'!$D$22,"") -> 7849.0471 | O5: =IF(ISNUMBER(H5),H5*'Conversion Factors'!$D$18,"") -> 248.21126 | P5: =IF(ISNUMBER(I5),I5*'Conversion Factors'!$D$18,"") -> 399.89592
A6: Hot Rolled | B6: A572 Gr.50 | C6: 29000 | D6: 11154 | E6: 0.3 | F6: 0.65 | G6: 0.49 | H6: 50 | I6: 58 | J6: =IF(ISNUMBER(C6),C6*'Conversion Factors'!$D$18,"") -> 199947.96 | K6: =IF(ISNUMBER(D6),D6*'Conversion Factors'!$D$18,"") -> 76904.123 | L6: =IF(ISNUMBER(F6),F6*'Conversion Factors'!$D$23,"") -> 11.7 | M6: =IF(ISNUMBER(G6),G6*'Conversion Factors'!$D$21,"") -> 76.972857 | N6: =IF(ISNUMBER(G6),G6*'Conversion Factors'!$D$22,"") -> 7849.0471 | O6: =IF(ISNUMBER(H6),H6*'Conversion Factors'!$D$18,"") -> 344.73786 | P6: =IF(ISNUMBER(I6),I6*'Conversion Factors'!$D$18,"") -> 399.89592
A7: Hot Rolled | B7: A992 | C7: 29000 | D7: 11154 | E7: 0.3 | F7: 0.65 | G7: 0.49 | H7: 50 | I7: 58 | J7: =IF(ISNUMBER(C7),C7*'Conversion Factors'!$D$18,"") -> 199947.96 | K7: =IF(ISNUMBER(D7),D7*'Conversion Factors'!$D$18,"") -> 76904.123 | L7: =IF(ISNUMBER(F7),F7*'Conversion Factors'!$D$23,"") -> 11.7 | M7: =IF(ISNUMBER(G7),G7*'Conversion Factors'!$D$21,"") -> 76.972857 | N7: =IF(ISNUMBER(G7),G7*'Conversion Factors'!$D$22,"") -> 7849.0471 | O7: =IF(ISNUMBER(H7),H7*'Conversion Factors'!$D$18,"") -> 344.73786 | P7: =IF(ISNUMBER(I7),I7*'Conversion Factors'!$D$18,"") -> 399.89592
A8: Hot Rolled | B8: A500 Gr.42 | C8: 29000 | D8: 11154 | E8: 0.3 | F8: 0.65 | G8: 0.49 | H8: 42 | I8: 58 | J8: =IF(ISNUMBER(C8),C8*'Conversion Factors'!$D$18,"") -> 199947.96 | K8: =IF(ISNUMBER(D8),D8*'Conversion Factors'!$D$18,"") -> 76904.123 | L8: =IF(ISNUMBER(F8),F8*'Conversion Factors'!$D$23,"") -> 11.7 | M8: =IF(ISNUMBER(G8),G8*'Conversion Factors'!$D$21,"") -> 76.972857 | N8: =IF(ISNUMBER(G8),G8*'Conversion Factors'!$D$22,"") -> 7849.0471 | O8: =IF(ISNUMBER(H8),H8*'Conversion Factors'!$D$18,"") -> 289.57981 | P8: =IF(ISNUMBER(I8),I8*'Conversion Factors'!$D$18,"") -> 399.89592
A9: Hot Rolled | B9: A500 Gr.46 | C9: 29000 | D9: 11154 | E9: 0.3 | F9: 0.65 | G9: 0.49 | H9: 46 | I9: 58 | J9: =IF(ISNUMBER(C9),C9*'Conversion Factors'!$D$18,"") -> 199947.96 | K9: =IF(ISNUMBER(D9),D9*'Conversion Factors'!$D$18,"") -> 76904.123 | L9: =IF(ISNUMBER(F9),F9*'Conversion Factors'!$D$23,"") -> 11.7 | M9: =IF(ISNUMBER(G9),G9*'Conversion Factors'!$D$21,"") -> 76.972857 | N9: =IF(ISNUMBER(G9),G9*'Conversion Factors'!$D$22,"") -> 7849.0471 | O9: =IF(ISNUMBER(H9),H9*'Conversion Factors'!$D$18,"") -> 317.15884 | P9: =IF(ISNUMBER(I9),I9*'Conversion Factors'!$D$18,"") -> 399.89592
A10: Cold Formed | B10: A570_33 | C10: 29500 | D10: 11346 | E10: 0.3 | F10: 0.65 | G10: 0.49 | H10: 33 | I10: 52 | J10: =IF(ISNUMBER(C10),C10*'Conversion Factors'!$D$18,"") -> 203395.34 | K10: =IF(ISNUMBER(D10),D10*'Conversion Factors'!$D$18,"") -> 78227.916 | L10: =IF(ISNUMBER(F10),F10*'Conversion Factors'!$D$23,"") -> 11.7 | M10: =IF(ISNUMBER(G10),G10*'Conversion Factors'!$D$21,"") -> 76.972857 | N10: =IF(ISNUMBER(G10),G10*'Conversion Factors'!$D$22,"") -> 7849.0471 | O10: =IF(ISNUMBER(H10),H10*'Conversion Factors'!$D$18,"") -> 227.52699 | P10: =IF(ISNUMBER(I10),I10*'Conversion Factors'!$D$18,"") -> 358.52738
A11: Cold Formed | B11: A607_C1_55 | C11: 29500 | D11: 11346 | E11: 0.3 | F11: 0.65 | G11: 0.49 | H11: 55 | I11: 70 | J11: =IF(ISNUMBER(C11),C11*'Conversion Factors'!$D$18,"") -> 203395.34 | K11: =IF(ISNUMBER(D11),D11*'Conversion Factors'!$D$18,"") -> 78227.916 | L11: =IF(ISNUMBER(F11),F11*'Conversion Factors'!$D$23,"") -> 11.7 | M11: =IF(ISNUMBER(G11),G11*'Conversion Factors'!$D$21,"") -> 76.972857 | N11: =IF(ISNUMBER(G11),G11*'Conversion Factors'!$D$22,"") -> 7849.0471 | O11: =IF(ISNUMBER(H11),H11*'Conversion Factors'!$D$18,"") -> 379.21165 | P11: =IF(ISNUMBER(I11),I11*'Conversion Factors'!$D$18,"") -> 482.63301
A12: Wood | B12: DF/SPine | E12: 0.3 | F12: 0.3 | G12: 0.035 | J12: =IF(ISNUMBER(C12),C12*'Conversion Factors'!$D$18,"") | K12: =IF(ISNUMBER(D12),D12*'Conversion Factors'!$D$18,"") | L12: =IF(ISNUMBER(F12),F12*'Conversion Factors'!$D$23,"") -> 5.4 | M12: =IF(ISNUMBER(G12),G12*'Conversion Factors'!$D$21,"") -> 5.4980612 | N12: =IF(ISNUMBER(G12),G12*'Conversion Factors'!$D$22,"") -> 560.64622 | O12: =IF(ISNUMBER(H12),H12*'Conversion Factors'!$D$18,"") | P12: =IF(ISNUMBER(I12),I12*'Conversion Factors'!$D$18,"")
A13: Wood | B13: HF/Spruce Fir | E13: 0.3 | F13: 0.3 | G13: 0.035 | J13: =IF(ISNUMBER(C13),C13*'Conversion Factors'!$D$18,"") | K13: =IF(ISNUMBER(D13),D13*'Conversion Factors'!$D$18,"") | L13: =IF(ISNUMBER(F13),F13*'Conversion Factors'!$D$23,"") -> 5.4 | M13: =IF(ISNUMBER(G13),G13*'Conversion Factors'!$D$21,"") -> 5.4980612 | N13: =IF(ISNUMBER(G13),G13*'Conversion Factors'!$D$22,"") -> 560.64622 | O13: =IF(ISNUMBER(H13),H13*'Conversion Factors'!$D$18,"") | P13: =IF(ISNUMBER(I13),I13*'Conversion Factors'!$D$18,"")
A14: Wood | B14: DF | E14: 0.3 | F14: 0.3 | G14: 0.035 | J14: =IF(ISNUMBER(C14),C14*'Conversion Factors'!$D$18,"") | K14: =IF(ISNUMBER(D14),D14*'Conversion Factors'!$D$18,"") | L14: =IF(ISNUMBER(F14),F14*'Conversion Factors'!$D$23,"") -> 5.4 | M14: =IF(ISNUMBER(G14),G14*'Conversion Factors'!$D$21,"") -> 5.4980612 | N14: =IF(ISNUMBER(G14),G14*'Conversion Factors'!$D$22,"") -> 560.64622 | O14: =IF(ISNUMBER(H14),H14*'Conversion Factors'!$D$18,"") | P14: =IF(ISNUMBER(I14),I14*'Conversion Factors'!$D$18,"")
A15: Wood | B15: SP | E15: 0.3 | F15: 0.3 | G15: 0.035 | J15: =IF(ISNUMBER(C15),C15*'Conversion Factors'!$D$18,"") | K15: =IF(ISNUMBER(D15),D15*'Conversion Factors'!$D$18,"") | L15: =IF(ISNUMBER(F15),F15*'Conversion Factors'!$D$23,"") -> 5.4 | M15: =IF(ISNUMBER(G15),G15*'Conversion Factors'!$D$21,"") -> 5.4980612 | N15: =IF(ISNUMBER(G15),G15*'Conversion Factors'!$D$22,"") -> 560.64622 | O15: =IF(ISNUMBER(H15),H15*'Conversion Factors'!$D$18,"") | P15: =IF(ISNUMBER(I15),I15*'Conversion Factors'!$D$18,"")
A16: Wood | B16: HF | E16: 0.3 | F16: 0.3 | G16: 0.035 | J16: =IF(ISNUMBER(C16),C16*'Conversion Factors'!$D$18,"") | K16: =IF(ISNUMBER(D16),D16*'Conversion Factors'!$D$18,"") | L16: =IF(ISNUMBER(F16),F16*'Conversion Factors'!$D$23,"") -> 5.4 | M16: =IF(ISNUMBER(G16),G16*'Conversion Factors'!$D$21,"") -> 5.4980612 | N16: =IF(ISNUMBER(G16),G16*'Conversion Factors'!$D$22,"") -> 560.64622 | O16: =IF(ISNUMBER(H16),H16*'Conversion Factors'!$D$18,"") | P16: =IF(ISNUMBER(I16),I16*'Conversion Factors'!$D$18,"")
A17: Wood | B17: SPF | E17: 0.3 | F17: 0.3 | G17: 0.035 | J17: =IF(ISNUMBER(C17),C17*'Conversion Factors'!$D$18,"") | K17: =IF(ISNUMBER(D17),D17*'Conversion Factors'!$D$18,"") | L17: =IF(ISNUMBER(F17),F17*'Conversion Factors'!$D$23,"") -> 5.4 | M17: =IF(ISNUMBER(G17),G17*'Conversion Factors'!$D$21,"") -> 5.4980612 | N17: =IF(ISNUMBER(G17),G17*'Conversion Factors'!$D$22,"") -> 560.64622 | O17: =IF(ISNUMBER(H17),H17*'Conversion Factors'!$D$18,"") | P17: =IF(ISNUMBER(I17),I17*'Conversion Factors'!$D$18,"")
A18: Wood | B18: 24F-1.8E DF_BAL | E18: 0.3 | F18: 0.3 | G18: 0.035 | J18: =IF(ISNUMBER(C18),C18*'Conversion Factors'!$D$18,"") | K18: =IF(ISNUMBER(D18),D18*'Conversion Factors'!$D$18,"") | L18: =IF(ISNUMBER(F18),F18*'Conversion Factors'!$D$23,"") -> 5.4 | M18: =IF(ISNUMBER(G18),G18*'Conversion Factors'!$D$21,"") -> 5.4980612 | N18: =IF(ISNUMBER(G18),G18*'Conversion Factors'!$D$22,"") -> 560.64622 | O18: =IF(ISNUMBER(H18),H18*'Conversion Factors'!$D$18,"") | P18: =IF(ISNUMBER(I18),I18*'Conversion Factors'!$D$18,"")
A19: Wood | B19: 24F-1.8E DF_UNBAL | E19: 0.3 | F19: 0.3 | G19: 0.035 | J19: =IF(ISNUMBER(C19),C19*'Conversion Factors'!$D$18,"") | K19: =IF(ISNUMBER(D19),D19*'Conversion Factors'!$D$18,"") | L19: =IF(ISNUMBER(F19),F19*'Conversion Factors'!$D$23,"") -> 5.4 | M19: =IF(ISNUMBER(G19),G19*'Conversion Factors'!$D$21,"") -> 5.4980612 | N19: =IF(ISNUMBER(G19),G19*'Conversion Factors'!$D$22,"") -> 560.64622 | O19: =IF(ISNUMBER(H19),H19*'Conversion Factors'!$D$18,"") | P19: =IF(ISNUMBER(I19),I19*'Conversion Factors'!$D$18,"")
A20: Wood | B20: 24F-1.8E SP_BAL | E20: 0.3 | F20: 0.3 | G20: 0.035 | J20: =IF(ISNUMBER(C20),C20*'Conversion Factors'!$D$18,"") | K20: =IF(ISNUMBER(D20),D20*'Conversion Factors'!$D$18,"") | L20: =IF(ISNUMBER(F20),F20*'Conversion Factors'!$D$23,"") -> 5.4 | M20: =IF(ISNUMBER(G20),G20*'Conversion Factors'!$D$21,"") -> 5.4980612 | N20: =IF(ISNUMBER(G20),G20*'Conversion Factors'!$D$22,"") -> 560.64622 | O20: =IF(ISNUMBER(H20),H20*'Conversion Factors'!$D$18,"") | P20: =IF(ISNUMBER(I20),I20*'Conversion Factors'!$D$18,"")
A21: Wood | B21: 24F-1.8E SP_UNBAL | E21: 0.3 | F21: 0.3 | G21: 0.035 | J21: =IF(ISNUMBER(C21),C21*'Conversion Factors'!$D$18,"") | K21: =IF(ISNUMBER(D21),D21*'Conversion Factors'!$D$18,"") | L21: =IF(ISNUMBER(F21),F21*'Conversion Factors'!$D$23,"") -> 5.4 | M21: =IF(ISNUMBER(G21),G21*'Conversion Factors'!$D$21,"") -> 5.4980612 | N21: =IF(ISNUMBER(G21),G21*'Conversion Factors'!$D$22,"") -> 560.64622 | O21: =IF(ISNUMBER(H21),H21*'Conversion Factors'!$D$18,"") | P21: =IF(ISNUMBER(I21),I21*'Conversion Factors'!$D$18,"")
A22: Wood | B22: LVL-PRL 1.5E_2250F | E22: 0.3 | F22: 0.3 | G22: 0.035 | J22: =IF(ISNUMBER(C22),C22*'Conversion Factors'!$D$18,"") | K22: =IF(ISNUMBER(D22),D22*'Conversion Factors'!$D$18,"") | L22: =IF(ISNUMBER(F22),F22*'Conversion Factors'!$D$23,"") -> 5.4 | M22: =IF(ISNUMBER(G22),G22*'Conversion Factors'!$D$21,"") -> 5.4980612 | N22: =IF(ISNUMBER(G22),G22*'Conversion Factors'!$D$22,"") -> 560.64622 | O22: =IF(ISNUMBER(H22),H22*'Conversion Factors'!$D$18,"") | P22: =IF(ISNUMBER(I22),I22*'Conversion Factors'!$D$18,"")
A23: Wood | B23: LVL-PRL 2.0E_2900F | E23: 0.3 | F23: 0.3 | G23: 0.035 | J23: =IF(ISNUMBER(C23),C23*'Conversion Factors'!$D$18,"") | K23: =IF(ISNUMBER(D23),D23*'Conversion Factors'!$D$18,"") | L23: =IF(ISNUMBER(F23),F23*'Conversion Factors'!$D$23,"") -> 5.4 | M23: =IF(ISNUMBER(G23),G23*'Conversion Factors'!$D$21,"") -> 5.4980612 | N23: =IF(ISNUMBER(G23),G23*'Conversion Factors'!$D$22,"") -> 560.64622 | O23: =IF(ISNUMBER(H23),H23*'Conversion Factors'!$D$18,"") | P23: =IF(ISNUMBER(I23),I23*'Conversion Factors'!$D$18,"")
